[1m[31mERROR   [0m asyncio:base_events.py:1758 Task exception was never retrieved
future: <Task finished name='Task-83' coro=<Dialog.accept() done, defined at C:\Users\lenovo\Desktop\nawat-automation-master\venv\lib\site-packages\playwright\_impl\_dialog.py:42> exception=Error('Cannot accept dialog which is already handled!')>
Traceback (most recent call last):
  File "C:\Users\lenovo\Desktop\nawat-automation-master\venv\lib\site-packages\playwright\_impl\_dialog.py", line 43, in accept
    await self._channel.send("accept", locals_to_params(locals()))
  File "C:\Users\lenovo\Desktop\nawat-automation-master\venv\lib\site-packages\playwright\_impl\_connection.py", line 61, in send
    return await self._connection.wrap_api_call(
  File "C:\Users\lenovo\Desktop\nawat-automation-master\venv\lib\site-packages\playwright\_impl\_connection.py", line 461, in wrap_api_call
    return await cb()
  File "C:\Users\lenovo\Desktop\nawat-automation-master\venv\lib\site-packages\playwright\_impl\_connection.py", line 96, in inner_send
    result = next(iter(done)).result()
playwright._impl._api_types.Error: Cannot accept dialog which is already handled!